Workbook

Sheet Instructions+Scoring Criteria
A1: (2) Financial Ratio Template
B3: INSTRUCTIONS
A4: 1 | B4: Each Bidder and Bidder Member must complete a separate Financial Ratio template for submission along with their completed Selection Questionnaire.
A5: 2 | B5: Bidders / Bidder Members are to input information within the YELLOW coloured cells on the next worksheet tab entitled "for Bidder Completion"
A7: Colour Guide to Cells and tabs
B8: Cells to be completed by Bidder/Bidder Member
B9: Contracting Authority formula or calculation using information input by the Bidder/Bidder Member
B10: Headings only, no inputs required or calculations made
B12: NOTES
A13: a) | B13: The Contracting Authority will evaluate the latest set of financial statements and only refer to the previous years’ information where the lead bidder or a bidder member scores two zeros against the latest year, in order to make a balanced assessment of the potential financial risk associated with the bidder.
A14: b) | B14: The information from the financial statements will be used to perform the ratios on the attached template. Each of the ratio calculations will be scored using a scale of 0 to 1, in accordance with the Scoring Matrix shown in the attached sheet.
A15: c) | B15: Bidders/Bidder Members will pass subject to achieving no more than one score of 0 across the measures used. The Scoring Criteria is outlined below.
A16: d) | B16: A Bidder/Bidder Member with two or more scores of 0 across the measures used to assess the financial statements based on the latest set of financial statements may fail. The Contracting Authority will then also evaluate the previous years’ information in order to make a balanced assessment of the potential financial risk associated with the bidder.
A17: e) | B17: Credit reports of Bidders/Bidder Members (and their Parent Company if applicable) may be obtained and reviewed, if necessary, to support the financial risk assessment in this part of the evaluation. This will only be considered as secondary to the Assessment of the Financial Statements.
A18: f) | B18: Contract Guidance Value: For the purposes of this calculation a guideline value of £7,738,000 will be used. This will then be divided by the Annual Turnover of the Bidder/Bidder Member and expressed as a percentage.
A19: g) | B19: Bidders/Bidder Members are required to complete this information accurately and in accordance with copy accounts documentation provided.
B20: SCORING CRITERIA
B21: Ratio / Measure
B22: Score | C22: Current Ratio | D22: Net Assets | E22: Capital Gearing | F22: ROCE | G22: Annual Guidance Value Ratio | H22: Net Profit Margin
B23: 1 | C23: > = 0.8:1 | D23: > = £0m | E23: < = 100% | F23: > = 0% | G23: < = 100% | H23: > = 0%
B24: 0 | C24: < 0.8:1 | D24: < £0m | E24: < 0% or > 100% | F24: < 0% | G24: > 100% | H24: < 0%

Sheet For BIDDER COMPLETION
A1: Financial Ratio Template
A2: Insert Bidder/Bidder Member Name: | B2: High Med Ltd (Lead Bidder)
A4: Complete the YELLOW cells within the following table for the MOST RECENT TWO YEARS, indicating which years these apply to in cell A5 and A31
A5: INSERT WHICH FINANCIAL YEAR(S) THE DATA RELATES TO | B5: Bidders Response | C5: Enter FY from audited accounts (High Med Ltd) - see 03 Supporting Evidence
A6: Profit & Loss
A7: Turnover | B7: 0 | C7: TBC - from audited accounts (do not estimate)
A8: Operating Profit | B8: 0
A9: Net Profit / (loss) (before taxation) | B9: 0
A10: Balance Sheet
A11: Current Assets | B11: 0
A12: Current Liabilities | B12: 0
A13: Long Term Liabilities | B13: 0
A14: Equity Shareholders' Funds | B14: 0
A15: Share of Contract Value expected by Bidder / Bidder Member
A16: Percentage of the Total Contract value that the Bidder/Bidder Member is expected to be responsible for? | B16: 0 | C16: Share of contract value % - to confirm at consortium agreement
A18: RATIOS | B18: Ratio Calculation
A19: Liquidity
A20: Current Ratio | B20: =SUM(B11/B12) | C20: =IF(B20>=0.8,1,0) | D20: Current Assets (inc. Stock) divided by Current Liabilities
A21: Net Assets | B21: =B11-B12 | C21: =IF(B21>=0,1,0) | D21: Current Assets less Current Liabilities
A22: Debt
A23: Capital Gearing | B23: =(B13/B14) | C23: =IF(AND(B23>=0%,B23<=100%),1,0) | D23: Long Term Liabilities divided by Shareholders Funds expressed as a percentage
A24: Profitability
A25: ROCE | B25: =B8/(B13+B14) | C25: =IF(B25>=0,1,0) | D25: Operating Profit divided by (Shareholders Funds plus Long Term Liabilities) expressed as a percentage
A26: Net Profit Margin | B26: =SUM(B9/B7) | C26: =IF(B26>=0,1,0) | D26: Net Profit before Taxation divided by Turnover expressed as a percentage
A27: Contract Guidance Value
A28: Annual Guidance Value Ratio | B28: ='Calculated AGV Ratio'!B9 | C28: ='Calculated AGV Ratio'!B10 | D28: Calculated Annual Guidance Value Ratio (see next worksheet), expressed as a percentage.
A30: Bidder Member 2: Dr Singh Hammond Road (key party)
A31: INSERT WHICH FINANCIAL YEAR(S) THE DATA RELATES TO | B31: Bidders Response | C31: Enter FY from audited accounts (Dr Singh Hammond Road) - see 03 Supporting Evidence
A32: Profit & Loss
A33: Turnover
A34: Operating Profit
A35: Net Profit / (loss) (before taxation)
A36: Balance Sheet
A37: Current Assets
A38: Current Liabilities
A39: Long Term Liabilities
A40: Equity Shareholders' Funds
A41: Share of Contract Value expected by Bidder / Bidder Member
A42: Percentage of the Total Contract value that the Bidder/Bidder Member is expected to be responsible for?
A44: RATIOS | B44: Ratio Calculation
...

Sheet Calculated AGV Ratio
A1: Calculated Annual Guidance Value Ratio
A3: ='For BIDDER COMPLETION'!A5
A4: ANNUAL GUIDANCE VALUE RATIO
A5: Annual Guidance Value Ratio Figure | B5: 1640000
A6: Percentage of the Total Contract value that the Bidder/Bidder Member is expected to be responsible for? | B6: ='For BIDDER COMPLETION'!B16
A7: Calculated Value of the Contract that the Bidder will be responsible for: | B7: =B5*B6
A8: Bidder Turnover | B8: ='For BIDDER COMPLETION'!B7
A9: Calculated Annual Guidance Value Ratio, expressed as a percentage | B9: =B7/B8
A10: SCORE | B10: =IF(B9<=100%,1,0)
A12: ='For BIDDER COMPLETION'!A31
A13: ANNUAL GUIDANCE VALUE RATIO
A14: Annual Guidance Value Ratio Figure | B14: 1640000
A15: Percentage of the Total Contract value that the Bidder/Bidder Member is expected to be responsible for? | B15: ='For BIDDER COMPLETION'!B42
A16: Calculated Value of the Contract that the Bidder will be responsible for: | B16: =B14*B15
A17: Bidder Turnover | B17: ='For BIDDER COMPLETION'!B33
A18: Calculated Annual Guidance Value Ratio, expressed as a percentage | B18: =B16/B17
A19: SCORE | B19: =IF(B18<=100%,1,0)
